Workbook

Sheet Trains
A1: N° origine | B1: Sens | C1: Jour | D1: Code mission | E1: Colonne1 | F1: Colonne2 | G1: Colonne3 | H1: Colonne4 | I1: Colonne5 | J1: Colonne6
A2: 146445 | B2: 0 | C2: 1 | D2: VIDE
A3: 143844 | B3: 0 | C3: 1 | D3: LARA
A4: 142446 | B4: 0 | C4: 1 | D4: SARA
A5: 192654 | B5: 0 | C5: 1 | D5: VIDE
A6: 196550 | B6: 0 | C6: Autre | D6: VIDE
A7: 146449 | B7: 0 | C7: 1 | D7: VIDE
A8: 143848 | B8: 0 | C8: 1 | D8: LARA
A9: 146143 | B9: 0 | C9: 1 | D9: VIDE
A10: 146250 | B10: 0 | C10: 1 | D10: VIDE
A11: 146145 | B11: 0 | C11: 1 | D11: VIDE
A12: 142144 | B12: 0 | C12: 1 | D12: ZORA
A13: 141243 | B13: 0 | C13: 1 | D13: JUJU
A14: 142450 | B14: 0 | C14: 1 | D14: SARA
A15: 141548 | B15: 0 | C15: 1 | D15: MONA
A16: 142246 | B16: 0 | C16: 1 | D16: VACK
A17: 146146 | B17: 0 | C17: 1 | D17: VIDE
A18: 146453 | B18: 0 | C18: 1 | D18: VIDE
... A112: 142466 | B112: 1 | C112: 1 | D112: VETO
A113: 146771 | B113: 1 | C113: Autre | D113: VIDE
A114: 142668 | B114: 1 | C114: 1 | D114: MICK
A115: 141647 | B115: 1 | C115: 1 | D115: CIME
A116: 142866 | B116: 1 | C116: 1 | D116: KOBE
A117: 143064 | B117: 1 | C117: 1 | D117: FOOT
A118: 142364 | B118: 1 | C118: 1 | D118: NICO
A119: 146167 | B119: 1 | C119: 1 | D119: VIDE
A120: 196070 | B120: 1 | C120: 1 | D120: VIDE
A121: 142162 | B121: 1 | C121: 1 | D121: GOTA
A122: 141564 | B122: 1 | C122: 1 | D122: MONA
A123: 142264 | B123: 1 | C123: 1 | D123: VACK
A124: 146469 | B124: 1 | C124: 1 | D124: VIDE
A125: 142564 | B125: 1 | C125: 1 | D125: GOTA
... A188: 143074 | B188: 1 | C188: 1 | D188: FOOT
A189: 912366 | B189: 0 | C189: 1
A190: 142374 | B190: 0 | C190: 1 | D190: LULU
A191: 149065 | B191: 0 | C191: 1 | D191: VIDE
A192: 141174 | B192: 0 | C192: 1 | D192: ROMI
A193: 142274 | B193: 0 | C193: 1 | D193: SIRI
A194: 141872 | B194: 0 | C194: 1 | D194: DEBO
A195: 141271 | B195: 0 | C195: 1 | D195: JUJU
...

Sheet Arrêts
A1: N° origine | B1: Parité | C1: Jour | D1: Gare | E1: Arrivée | F1: Départ | G1: Passage | H1: Voie
A2: 142840 | B2: 0 | C2: 7 | D2: D | F2: 0.15127315 | H2: 1
A3: 142840 | B3: 0 | C3: 7 | D3: SXE | E3: 0.15428241 | F3: 0.15474537 | H3: 2
A4: 142840 | B4: 0 | C4: 7 | D4: SCW | E4: 0.15775463 | F4: 0.15821759 | H4: 2
A5: 142840 | B5: 0 | C5: 7 | D5: BRW | E5: 0.16076389 | F5: 0.16122685 | H5: 2
A6: 142840 | B6: 0 | C6: 7 | D6: BIH | E6: 0.16319444 | F6: 0.16365741 | H6: 2
A7: 142840 | B7: 0 | C7: 7 | D7: ELY | E7: 0.16574074 | F7: 0.1662037 | H7: 2
A8: 142840 | B8: 0 | C8: 7 | D8: ARP | E8: 0.16782407 | F8: 0.16828704 | H8: 2
A9: 142840 | B9: 0 | C9: 7 | D9: NG | E9: 0.17013889 | F9: 0.17060185 | H9: 2
A10: 142840 | B10: 0 | C10: 7 | D10: BY | E10: 0.17361111 | F10: 0.1744213 | H10: 6
A11: 142840 | B11: 0 | C11: 7 | D11: SHO | E11: 0.17673611 | F11: 0.17719907 | H11: 2BIS
A12: 142840 | B12: 0 | C12: 7 | D12: SXG | E12: 0.1787037 | F12: 0.17916667 | H12: 2BIS
A13: 142840 | B13: 0 | C13: 7 | D13: EYO | E13: 0.18090278 | F13: 0.18148148 | H13: 2BIS
A14: 142840 | B14: 0 | C14: 7 | D14: SAO | E14: 0.18275463 | F14: 0.18333333 | H14: 2BIS
A15: 142840 | B15: 0 | C15: 7 | D15: JY | E15: 0.18553241 | F15: 0.1869213 | H15: 2BIS
A16: 142840 | B16: 0 | C16: 7 | D16: BFM | E16: 0.19444444 | F16: 0.19513889 | H16: 2BIS
A17: 142840 | B17: 0 | C17: 7 | D17: PZB | E17: 0.19699074 | H17: 1S
A18: 142444 | B18: 0 | C18: 7 | D18: SME | F18: 0.17488426 | H18: UNIQUE
A19: 142444 | B19: 0 | C19: 7 | D19: ETP | E19: 0.17766204 | F19: 0.178125 | H19: 2BIS
A20: 142444 | B20: 0 | C20: 7 | D20: ETY | E20: 0.1818287 | F20: 0.18229167 | H20: 2BIS
A21: 142444 | B21: 0 | C21: 7 | D21: CHK | E21: 0.18402778 | F21: 0.18449074 | H21: 2BIS
A22: 142444 | B22: 0 | C22: 7 | D22: LYO | E22: 0.18645833 | F22: 0.1869213 | H22: 2BIS
A23: 142444 | B23: 0 | C23: 7 | D23: BSO | E23: 0.18877315 | F23: 0.18923611 | H23: 2BIS
A24: 142444 | B24: 0 | C24: 7 | D24: MSX | E24: 0.19143519 | F24: 0.19189815 | H24: 2BIS
A25: 142444 | B25: 0 | C25: 7 | D25: BY | E25: 0.19456019 | F25: 0.19525463 | H25: 2BIS
A26: 142444 | B26: 0 | C26: 7 | D26: SHO | E26: 0.19756944 | F26: 0.19803241 | H26: 2BIS
A27: 142444 | B27: 0 | C27: 7 | D27: SXG | E27: 0.19953704 | F27: 0.2 | H27: 2BIS
A28: 142444 | B28: 0 | C28: 7 | D28: EYO | E28: 0.20173611 | F28: 0.20231481 | H28: 2BIS
A29: 142444 | B29: 0 | C29: 7 | D29: SAO | E29: 0.20358796 | F29: 0.20416667 | H29: 2BIS
A30: 142444 | B30: 0 | C30: 7 | D30: JY | E30: 0.20636574 | F30: 0.20706019 | H30: 2BIS
... A32: 142444 | B32: 0 | C32: 7 | D32: PZB | E32: 0.21747685 | F32: 0.21805556 | H32: 2S
A33: 142444 | B33: 0 | C33: 7 | D33: SHL | E33: 0.22025463 | F33: 0.22083333 | H33: 2
A34: 142444 | B34: 0 | C34: 7 | D34: MDS | E34: 0.22303241 | H34: 1
A35: 142848 | B35: 0 | C35: 7 | D35: D | F35: 0.19293981 | H35: 1
A36: 142848 | B36: 0 | C36: 7 | D36: SXE | E36: 0.19594907 | F36: 0.19641204 | H36: 2
A37: 142848 | B37: 0 | C37: 7 | D37: SCW | E37: 0.1994213 | F37: 0.19988426 | H37: 2
A38: 142848 | B38: 0 | C38: 7 | D38: BRW | E38: 0.20243056 | F38: 0.20289352 | H38: 2
A39: 142848 | B39: 0 | C39: 7 | D39: BIH | E39: 0.20486111 | F39: 0.20532407 | H39: 2
A40: 142848 | B40: 0 | C40: 7 | D40: ELY | E40: 0.20740741 | F40: 0.20787037 | H40: 2
A41: 142848 | B41: 0 | C41: 7 | D41: ARP | E41: 0.20949074 | F41: 0.2099537 | H41: 2
...

Sheet Param
A1: !ntitulé | B1: Valeur | D1: Jours | E1: Abréviation | F1: N°
A2: Nombre connexions max par gare | B2: 6 | D2: Lundi | E2: Lu | F2: 1
D3: Mardi | E3: Ma | F3: 2
D4: Mercredi | E4: Me | F4: 3
D5: Jeudi | E5: Je | F5: 4
D6: Vendredi | E6: Ve | F6: 5
D7: Samedi | E7: Sa | F7: 6
D8: Dimanche | E8: Di | F8: 7
D9: JOB | E9: J | F9: 1;2;3;4;5
D10: WE | E10: W | F10: 6;7

Sheet Gares
A1: Abv | B1: Gare | C1: Variants (même plate-forme) | D1: Gare de rebroussement | E1: Sens des gares inversé (normalement donné dans le sens pair) = Sens inversé pour la ligne C | F1: Nombre de connexions de la gare | G1: Nombre de connexions où la gare est appelée | H1: OK? Nombre de connexions de la gare = Nombre de connexions où la gare est appelée ? | I1: De | J1: Vers1 | K1: Vers2 | L1: Vers3 | M1: Vers4 | N1: Vers5 | O1: Vers6 | P1: SensDe1 | Q1: SensDe2 | R1: SensDe3 | S1: SensDe4 | T1: SensDe5 | U1: SensDe6 | V1: SensVers1 | W1: SensVers2 | X1: SensVers3 | Y1: SensVers4 | Z1: SensVers5 | AA1: SensVers6
E2: & : connexion sens inversé (gare connectée en dessous dans la liste au lieu d'être au dessus ou inversement) | J2: $ : connexion avec rbt | L2: @ : connexion avec changement de parité
A3: DA | B3: Dourdan La Forêt | D3: I | F3: =COUNTA($J3:$N3) -> 2 | G3: {=SUM(IF(SUBSTITUTE(SUBSTITUTE(SUBSTITUTE(OFFSET($J$3,0,0,ROWS(Gares[Vers1]),Param!$B$2),"&",""),"$",""),"@","")=$I3,1,0))} -> 2 | H3: =IF(F3=G3,1,0) -> 1 | I3: =Gares[[#This Row],[Abv]] -> DA | J3: D | K3: D-GB | P3: =IF(Gares[[#This Row],[Vers1]]="",0,IF(_xlfn.XOR(ISERROR(MATCH(SUBSTITUTE(SUBSTITUTE(SUBSTITUTE(Gares[[#This Row],[Vers1]],"&",""),"$",""),"@",""),$I2:$I$2,0)),NOT(ISERROR(FIND("&",Gares[[#This Row],[Vers1]])))),2,1)) -> 2 | Q3: =IF(Gares[[#This Row],[Vers2]]="",0,IF(_xlfn.XOR(ISERROR(MATCH(SUBSTITUTE(SUBSTITUTE(SUBSTITUTE(Gares[[#This Row],[Vers2]],"&",""),"$",""),"@",""),$I2:$I$2,0)),NOT(ISERROR(FIND("&",Gares[[#This Row],[Vers2]])))),2,1)) -> 2 | R3: =IF(Gares[[#This Row],[Vers3]]="",0,IF(_xlfn.XOR(ISERROR(MATCH(SUBSTITUTE(SUBSTITUTE(SUBSTITUTE(Gares[[#This Row],[Vers3]],"&",""),"$",""),"@",""),$I2:$I$2,0)),NOT(ISERROR(FIND("&",Gares[[#This Row],[Vers3]])))),2,1)) -> 0 | S3: =IF(Gares[[#This Row],[Vers4]]="",0,IF(_xlfn.XOR(ISERROR(MATCH(SUBSTITUTE(SUBSTITUTE(SUBSTITUTE(Gares[[#This Row],[Vers4]],"&",""),"$",""),"@",""),$I2:$I$2,0)),NOT(ISERROR(FIND("&",Gares[[#This Row],[Vers4]])))),2,1)) -> 0 | T3: =IF(Gares[[#This Row],[Vers5]]="",0,IF(_xlfn.XOR(ISERROR(MATCH(SUBSTITUTE(SUBSTITUTE(SUBSTITUTE(Gares[[#This Row],[Vers5]],"&",""),"$",""),"@",""),$I2:$I$2,0)),NOT(ISERROR(FIND("&",Gares[[#This Row],[Vers5]])))),2,1)) -> 0 | U3: =IF(Gares[[#This Row],[Vers6]]="",0,IF(_xlfn.XOR(ISERROR(MATCH(SUBSTITUTE(SUBSTITUTE(SUBSTITUTE(Gares[[#This Row],[Vers6]],"&",""),"$",""),"@",""),$I2:$I$2,0)),NOT(ISERROR(FIND("&",Gares[[#This Row],[Vers6]])))),2,1)) -> 0 | V3: =IF(Gares[[#This Row],[SensDe1]]=0,0,IF(ISERROR(FIND("$",Gares[[#This Row],[Vers1]]))*ISERROR(FIND("@",Gares[[#This Row],[Vers1]])),Gares[[#This Row],[SensDe1]],3-Gares[[#This Row],[SensDe1]])) -> 2 | W3: =IF(Gares[[#This Row],[SensDe2]]=0,0,IF(ISERROR(FIND("$",Gares[[#This Row],[Vers2]]))*ISERROR(FIND("@",Gares[[#This Row],[Vers2]])),Gares[[#This Row],[SensDe2]],3-Gares[[#This Row],[SensDe2]])) -> 2 | X3: =IF(Gares[[#This Row],[SensDe3]]=0,0,IF(ISERROR(FIND("$",Gares[[#This Row],[Vers3]]))*ISERROR(FIND("@",Gares[[#This Row],[Vers3]])),Gares[[#This Row],[SensDe3]],3-Gares[[#This Row],[SensDe3]])) -> 0 | Y3: =IF(Gares[[#This Row],[SensDe4]]=0,0,IF(ISERROR(FIND("$",Gares[[#This Row],[Vers4]]))*ISERROR(FIND("@",Gares[[#This Row],[Vers4]])),Gares[[#This Row],[SensDe4]],3-Gares[[#This Row],[SensDe4]])) -> 0 | Z3: =IF(Gares[[#This Row],[SensDe5]]=0,0,IF(ISERROR(FIND("$",Gares[[#This Row],[Vers5]]))*ISERROR(FIND("@",Gares[[#This Row],[Vers5]])),Gares[[#This Row],[SensDe5]],3-Gares[[#This Row],[SensDe5]])) -> 0 | AA3: =IF(Gares[[#This Row],[SensDe6]]=0,0,IF(ISERROR(FIND("$",Gares[[#This Row],[Vers6]]))*ISERROR(FIND("@",Gares[[#This Row],[Vers6]])),Gares[[#This Row],[SensDe6]],3-Gares[[#This Row],[SensDe6]])) -> 0
A4: DA-FI | B4: Dourdan La Forêt - Garages | D4: I | F4: =COUNTA($J4:$N4) -> 2 | G4: {=SUM(IF(SUBSTITUTE(SUBSTITUTE(SUBSTITUTE(OFFSET($J$3,0,0,ROWS(Gares[Vers1]),Param!$B$2),"&",""),"$",""),"@","")=$I4,1,0))} -> 2 | H4: =IF(F4=G4,1,0) -> 1 | I4: =Gares[[#This Row],[Abv]] -> DA-FI | J4: D | K4: D-GB | P4: =IF(Gares[[#This Row],[Vers1]]="",0,IF(_xlfn.XOR(ISERROR(MATCH(SUBSTITUTE(SUBSTITUTE(SUBSTITUTE(Gares[[#This Row],[Vers1]],"&",""),"$",""),"@",""),$I$2:$I3,0)),NOT(ISERROR(FIND("&",Gares[[#This Row],[Vers1]])))),2,1)) -> 2 | Q4: =IF(Gares[[#This Row],[Vers2]]="",0,IF(_xlfn.XOR(ISERROR(MATCH(SUBSTITUTE(SUBSTITUTE(SUBSTITUTE(Gares[[#This Row],[Vers2]],"&",""),"$",""),"@",""),$I$2:$I3,0)),NOT(ISERROR(FIND("&",Gares[[#This Row],[Vers2]])))),2,1)) -> 2 | R4: =IF(Gares[[#This Row],[Vers3]]="",0,IF(_xlfn.XOR(ISERROR(MATCH(SUBSTITUTE(SUBSTITUTE(SUBSTITUTE(Gares[[#This Row],[Vers3]],"&",""),"$",""),"@",""),$I$2:$I3,0)),NOT(ISERROR(FIND("&",Gares[[#This Row],[Vers3]])))),2,1)) -> 0 | S4: =IF(Gares[[#This Row],[Vers4]]="",0,IF(_xlfn.XOR(ISERROR(MATCH(SUBSTITUTE(SUBSTITUTE(SUBSTITUTE(Gares[[#This Row],[Vers4]],"&",""),"$",""),"@",""),$I$2:$I3,0)),NOT(ISERROR(FIND("&",Gares[[#This Row],[Vers4]])))),2,1)) -> 0 | T4: =IF(Gares[[#This Row],[Vers5]]="",0,IF(_xlfn.XOR(ISERROR(MATCH(SUBSTITUTE(SUBSTITUTE(SUBSTITUTE(Gares[[#This Row],[Vers5]],"&",""),"$",""),"@",""),$I$2:$I3,0)),NOT(ISERROR(FIND("&",Gares[[#This Row],[Vers5]])))),2,1)) -> 0 | U4: =IF(Gares[[#This Row],[Vers6]]="",0,IF(_xlfn.XOR(ISERROR(MATCH(SUBSTITUTE(SUBSTITUTE(SUBSTITUTE(Gares[[#This Row],[Vers6]],"&",""),"$",""),"@",""),$I$2:$I3,0)),NOT(ISERROR(FIND("&",Gares[[#This Row],[Vers6]])))),2,1)) -> 0 | V4: =IF(Gares[[#This Row],[SensDe1]]=0,0,IF(ISERROR(FIND("$",Gares[[#This Row],[Vers1]]))*ISERROR(FIND("@",Gares[[#This Row],[Vers1]])),Gares[[#This Row],[SensDe1]],3-Gares[[#This Row],[SensDe1]])) -> 2 | W4: =IF(Gares[[#This Row],[SensDe2]]=0,0,IF(ISERROR(FIND("$",Gares[[#This Row],[Vers2]]))*ISERROR(FIND("@",Gares[[#This Row],[Vers2]])),Gares[[#This Row],[SensDe2]],3-Gares[[#This Row],[SensDe2]])) -> 2 | X4: =IF(Gares[[#This Row],[SensDe3]]=0,0,IF(ISERROR(FIND("$",Gares[[#This Row],[Vers3]]))*ISERROR(FIND("@",Gares[[#This Row],[Vers3]])),Gares[[#This Row],[SensDe3]],3-Gares[[#This Row],[SensDe3]])) -> 0 | Y4: =IF(Gares[[#This Row],[SensDe4]]=0,0,IF(ISERROR(FIND("$",Gares[[#This Row],[Vers4]]))*ISERROR(FIND("@",Gares[[#This Row],[Vers4]])),Gares[[#This Row],[SensDe4]],3-Gares[[#This Row],[SensDe4]])) -> 0 | Z4: =IF(Gares[[#This Row],[SensDe5]]=0,0,IF(ISERROR(FIND("$",Gares[[#This Row],[Vers5]]))*ISERROR(FIND("@",Gares[[#This Row],[Vers5]])),Gares[[#This Row],[SensDe5]],3-Gares[[#This Row],[SensDe5]])) -> 0 | AA4: =IF(Gares[[#This Row],[SensDe6]]=0,0,IF(ISERROR(FIND("$",Gares[[#This Row],[Vers6]]))*ISERROR(FIND("@",Gares[[#This Row],[Vers6]])),Gares[[#This Row],[SensDe6]],3-Gares[[#This Row],[SensDe6]])) -> 0
A5: D-GB | B5: Dourdan - Garages | D5: IP | F5: =COUNTA($J5:$N5) -> 4 | G5: {=SUM(IF(SUBSTITUTE(SUBSTITUTE(SUBSTITUTE(OFFSET($J$3,0,0,ROWS(Gares[Vers1]),Param!$B$2),"&",""),"$",""),"@","")=$I5,1,0))} -> 4 | H5: =IF(F5=G5,1,0) -> 1 | I5: =Gares[[#This Row],[Abv]] -> D-GB | J5: SXE | K5: D$& | L5: DA | M5: DA-FI | P5: =IF(Gares[[#This Row],[Vers1]]="",0,IF(_xlfn.XOR(ISERROR(MATCH(SUBSTITUTE(SUBSTITUTE(SUBSTITUTE(Gares[[#This Row],[Vers1]],"&",""),"$",""),"@",""),$I$2:$I4,0)),NOT(ISERROR(FIND("&",Gares[[#This Row],[Vers1]])))),2,1)) -> 2 | Q5: =IF(Gares[[#This Row],[Vers2]]="",0,IF(_xlfn.XOR(ISERROR(MATCH(SUBSTITUTE(SUBSTITUTE(SUBSTITUTE(Gares[[#This Row],[Vers2]],"&",""),"$",""),"@",""),$I$2:$I4,0)),NOT(ISERROR(FIND("&",Gares[[#This Row],[Vers2]])))),2,1)) -> 1 | R5: =IF(Gares[[#This Row],[Vers3]]="",0,IF(_xlfn.XOR(ISERROR(MATCH(SUBSTITUTE(SUBSTITUTE(SUBSTITUTE(Gares[[#This Row],[Vers3]],"&",""),"$",""),"@",""),$I$2:$I4,0)),NOT(ISERROR(FIND("&",Gares[[#This Row],[Vers3]])))),2,1)) -> 1 | S5: =IF(Gares[[#This Row],[Vers4]]="",0,IF(_xlfn.XOR(ISERROR(MATCH(SUBSTITUTE(SUBSTITUTE(SUBSTITUTE(Gares[[#This Row],[Vers4]],"&",""),"$",""),"@",""),$I$2:$I4,0)),NOT(ISERROR(FIND("&",Gares[[#This Row],[Vers4]])))),2,1)) -> 1 | T5: =IF(Gares[[#This Row],[Vers5]]="",0,IF(_xlfn.XOR(ISERROR(MATCH(SUBSTITUTE(SUBSTITUTE(SUBSTITUTE(Gares[[#This Row],[Vers5]],"&",""),"$",""),"@",""),$I$2:$I4,0)),NOT(ISERROR(FIND("&",Gares[[#This Row],[Vers5]])))),2,1)) -> 0 | U5: =IF(Gares[[#This Row],[Vers6]]="",0,IF(_xlfn.XOR(ISERROR(MATCH(SUBSTITUTE(SUBSTITUTE(SUBSTITUTE(Gares[[#This Row],[Vers6]],"&",""),"$",""),"@",""),$I$2:$I4,0)),NOT(ISERROR(FIND("&",Gares[[#This Row],[Vers6]])))),2,1)) -> 0 | V5: =IF(Gares[[#This Row],[SensDe1]]=0,0,IF(ISERROR(FIND("$",Gares[[#This Row],[Vers1]]))*ISERROR(FIND("@",Gares[[#This Row],[Vers1]])),Gares[[#This Row],[SensDe1]],3-Gares[[#This Row],[SensDe1]])) -> 2 | W5: =IF(Gares[[#This Row],[SensDe2]]=0,0,IF(ISERROR(FIND("$",Gares[[#This Row],[Vers2]]))*ISERROR(FIND("@",Gares[[#This Row],[Vers2]])),Gares[[#This Row],[SensDe2]],3-Gares[[#This Row],[SensDe2]])) -> 2 | X5: =IF(Gares[[#This Row],[SensDe3]]=0,0,IF(ISERROR(FIND("$",Gares[[#This Row],[Vers3]]))*ISERROR(FIND("@",Gares[[#This Row],[Vers3]])),Gares[[#This Row],[SensDe3]],3-Gares[[#This Row],[SensDe3]])) -> 1 | Y5: =IF(Gares[[#This Row],[SensDe4]]=0,0,IF(ISERROR(FIND("$",Gares[[#This Row],[Vers4]]))*ISERROR(FIND("@",Gares[[#This Row],[Vers4]])),Gares[[#This Row],[SensDe4]],3-Gares[[#This Row],[SensDe4]])) -> 1 | Z5: =IF(Gares[[#This Row],[SensDe5]]=0,0,IF(ISERROR(FIND("$",Gares[[#This Row],[Vers5]]))*ISERROR(FIND("@",Gares[[#This Row],[Vers5]])),Gares[[#This Row],[SensDe5]],3-Gares[[#This Row],[SensDe5]])) -> 0 | AA5: =IF(Gares[[#This Row],[SensDe6]]=0,0,IF(ISERROR(FIND("$",Gares[[#This Row],[Vers6]]))*ISERROR(FIND("@",Gares[[#This Row],[Vers6]])),Gares[[#This Row],[SensDe6]],3-Gares[[#This Row],[SensDe6]])) -> 0
A6: D | B6: Dourdan | D6: IP | F6: =COUNTA($J6:$N6) -> 4 | G6: {=SUM(IF(SUBSTITUTE(SUBSTITUTE(SUBSTITUTE(OFFSET($J$3,0,0,ROWS(Gares[Vers1]),Param!$B$2),"&",""),"$",""),"@","")=$I6,1,0))} -> 4 | H6: =IF(F6=G6,1,0) -> 1 | I6: =Gares[[#This Row],[Abv]] -> D | J6: =I7 -> SXE | K6: D-GB$ | L6: DA | M6: DA-FI | P6: =IF(Gares[[#This Row],[Vers1]]="",0,IF(_xlfn.XOR(ISERROR(MATCH(SUBSTITUTE(SUBSTITUTE(SUBSTITUTE(Gares[[#This Row],[Vers1]],"&",""),"$",""),"@",""),$I$2:$I5,0)),NOT(ISERROR(FIND("&",Gares[[#This Row],[Vers1]])))),2,1)) -> 2 | Q6: =IF(Gares[[#This Row],[Vers2]]="",0,IF(_xlfn.XOR(ISERROR(MATCH(SUBSTITUTE(SUBSTITUTE(SUBSTITUTE(Gares[[#This Row],[Vers2]],"&",""),"$",""),"@",""),$I$2:$I5,0)),NOT(ISERROR(FIND("&",Gares[[#This Row],[Vers2]])))),2,1)) -> 1 | R6: =IF(Gares[[#This Row],[Vers3]]="",0,IF(_xlfn.XOR(ISERROR(MATCH(SUBSTITUTE(SUBSTITUTE(SUBSTITUTE(Gares[[#This Row],[Vers3]],"&",""),"$",""),"@",""),$I$2:$I5,0)),NOT(ISERROR(FIND("&",Gares[[#This Row],[Vers3]])))),2,1)) -> 1 | S6: =IF(Gares[[#This Row],[Vers4]]="",0,IF(_xlfn.XOR(ISERROR(MATCH(SUBSTITUTE(SUBSTITUTE(SUBSTITUTE(Gares[[#This Row],[Vers4]],"&",""),"$",""),"@",""),$I$2:$I5,0)),NOT(ISERROR(FIND("&",Gares[[#This Row],[Vers4]])))),2,1)) -> 1 | T6: =IF(Gares[[#This Row],[Vers5]]="",0,IF(_xlfn.XOR(ISERROR(MATCH(SUBSTITUTE(SUBSTITUTE(SUBSTITUTE(Gares[[#This Row],[Vers5]],"&",""),"$",""),"@",""),$I$2:$I5,0)),NOT(ISERROR(FIND("&",Gares[[#This Row],[Vers5]])))),2,1)) -> 0 | U6: =IF(Gares[[#This Row],[Vers6]]="",0,IF(_xlfn.XOR(ISERROR(MATCH(SUBSTITUTE(SUBSTITUTE(SUBSTITUTE(Gares[[#This Row],[Vers6]],"&",""),"$",""),"@",""),$I$2:$I5,0)),NOT(ISERROR(FIND("&",Gares[[#This Row],[Vers6]])))),2,1)) -> 0 | V6: =IF(Gares[[#This Row],[SensDe1]]=0,0,IF(ISERROR(FIND("$",Gares[[#This Row],[Vers1]]))*ISERROR(FIND("@",Gares[[#This Row],[Vers1]])),Gares[[#This Row],[SensDe1]],3-Gares[[#This Row],[SensDe1]])) -> 2 | W6: =IF(Gares[[#This Row],[SensDe2]]=0,0,IF(ISERROR(FIND("$",Gares[[#This Row],[Vers2]]))*ISERROR(FIND("@",Gares[[#This Row],[Vers2]])),Gares[[#This Row],[SensDe2]],3-Gares[[#This Row],[SensDe2]])) -> 2 | X6: =IF(Gares[[#This Row],[SensDe3]]=0,0,IF(ISERROR(FIND("$",Gares[[#This Row],[Vers3]]))*ISERROR(FIND("@",Gares[[#This Row],[Vers3]])),Gares[[#This Row],[SensDe3]],3-Gares[[#This Row],[SensDe3]])) -> 1 | Y6: =IF(Gares[[#This Row],[SensDe4]]=0,0,IF(ISERROR(FIND("$",Gares[[#This Row],[Vers4]]))*ISERROR(FIND("@",Gares[[#This Row],[Vers4]])),Gares[[#This Row],[SensDe4]],3-Gares[[#This Row],[SensDe4]])) -> 1 | Z6: =IF(Gares[[#This Row],[SensDe5]]=0,0,IF(ISERROR(FIND("$",Gares[[#This Row],[Vers5]]))*ISERROR(FIND("@",Gares[[#This Row],[Vers5]])),Gares[[#This Row],[SensDe5]],3-Gares[[#This Row],[SensDe5]])) -> 0 | AA6: =IF(Gares[[#This Row],[SensDe6]]=0,0,IF(ISERROR(FIND("$",Gares[[#This Row],[Vers6]]))*ISERROR(FIND("@",Gares[[#This Row],[Vers6]])),Gares[[#This Row],[SensDe6]],3-Gares[[#This Row],[SensDe6]])) -> 0
A7: SXE | B7: Sermaise | F7: =COUNTA($J7:$N7) -> 3 | G7: {=SUM(IF(SUBSTITUTE(SUBSTITUTE(SUBSTITUTE(OFFSET($J$3,0,0,ROWS(Gares[Vers1]),Param!$B$2),"&",""),"$",""),"@","")=$I7,1,0))} -> 3 | H7: =IF(F7=G7,1,0) -> 1 | I7: =Gares[[#This Row],[Abv]] -> SXE | J7: =I8 -> SCW | K7: D | L7: D-GB | P7: =IF(Gares[[#This Row],[Vers1]]="",0,IF(_xlfn.XOR(ISERROR(MATCH(SUBSTITUTE(SUBSTITUTE(SUBSTITUTE(Gares[[#This Row],[Vers1]],"&",""),"$",""),"@",""),$I$2:$I6,0)),NOT(ISERROR(FIND("&",Gares[[#This Row],[Vers1]])))),2,1)) -> 2 | Q7: =IF(Gares[[#This Row],[Vers2]]="",0,IF(_xlfn.XOR(ISERROR(MATCH(SUBSTITUTE(SUBSTITUTE(SUBSTITUTE(Gares[[#This Row],[Vers2]],"&",""),"$",""),"@",""),$I$2:$I6,0)),NOT(ISERROR(FIND("&",Gares[[#This Row],[Vers2]])))),2,1)) -> 1 | R7: =IF(Gares[[#This Row],[Vers3]]="",0,IF(_xlfn.XOR(ISERROR(MATCH(SUBSTITUTE(SUBSTITUTE(SUBSTITUTE(Gares[[#This Row],[Vers3]],"&",""),"$",""),"@",""),$I$2:$I6,0)),NOT(ISERROR(FIND("&",Gares[[#This Row],[Vers3]])))),2,1)) -> 1 | S7: =IF(Gares[[#This Row],[Vers4]]="",0,IF(_xlfn.XOR(ISERROR(MATCH(SUBSTITUTE(SUBSTITUTE(SUBSTITUTE(Gares[[#This Row],[Vers4]],"&",""),"$",""),"@",""),$I$2:$I6,0)),NOT(ISERROR(FIND("&",Gares[[#This Row],[Vers4]])))),2,1)) -> 0 | T7: =IF(Gares[[#This Row],[Vers5]]="",0,IF(_xlfn.XOR(ISERROR(MATCH(SUBSTITUTE(SUBSTITUTE(SUBSTITUTE(Gares[[#This Row],[Vers5]],"&",""),"$",""),"@",""),$I$2:$I6,0)),NOT(ISERROR(FIND("&",Gares[[#This Row],[Vers5]])))),2,1)) -> 0 | U7: =IF(Gares[[#This Row],[Vers6]]="",0,IF(_xlfn.XOR(ISERROR(MATCH(SUBSTITUTE(SUBSTITUTE(SUBSTITUTE(Gares[[#This Row],[Vers6]],"&",""),"$",""),"@",""),$I$2:$I6,0)),NOT(ISERROR(FIND("&",Gares[[#This Row],[Vers6]])))),2,1)) -> 0 | V7: =IF(Gares[[#This Row],[SensDe1]]=0,0,IF(ISERROR(FIND("$",Gares[[#This Row],[Vers1]]))*ISERROR(FIND("@",Gares[[#This Row],[Vers1]])),Gares[[#This Row],[SensDe1]],3-Gares[[#This Row],[SensDe1]])) -> 2 | W7: =IF(Gares[[#This Row],[SensDe2]]=0,0,IF(ISERROR(FIND("$",Gares[[#This Row],[Vers2]]))*ISERROR(FIND("@",Gares[[#This Row],[Vers2]])),Gares[[#This Row],[SensDe2]],3-Gares[[#This Row],[SensDe2]])) -> 1 | X7: =IF(Gares[[#This Row],[SensDe3]]=0,0,IF(ISERROR(FIND("$",Gares[[#This Row],[Vers3]]))*ISERROR(FIND("@",Gares[[#This Row],[Vers3]])),Gares[[#This Row],[SensDe3]],3-Gares[[#This Row],[SensDe3]])) -> 1 | Y7: =IF(Gares[[#This Row],[SensDe4]]=0,0,IF(ISERROR(FIND("$",Gares[[#This Row],[Vers4]]))*ISERROR(FIND("@",Gares[[#This Row],[Vers4]])),Gares[[#This Row],[SensDe4]],3-Gares[[#This Row],[SensDe4]])) -> 0 | Z7: =IF(Gares[[#This Row],[SensDe5]]=0,0,IF(ISERROR(FIND("$",Gares[[#This Row],[Vers5]]))*ISERROR(FIND("@",Gares[[#This Row],[Vers5]])),Gares[[#This Row],[SensDe5]],3-Gares[[#This Row],[SensDe5]])) -> 0 | AA7: =IF(Gares[[#This Row],[SensDe6]]=0,0,IF(ISERROR(FIND("$",Gares[[#This Row],[Vers6]]))*ISERROR(FIND("@",Gares[[#This Row],[Vers6]])),Gares[[#This Row],[SensDe6]],3-Gares[[#This Row],[SensDe6]])) -> 0
A8: SCW | B8: Saint-Chéron | F8: =COUNTA($J8:$N8) -> 2 | G8: {=SUM(IF(SUBSTITUTE(SUBSTITUTE(SUBSTITUTE(OFFSET($J$3,0,0,ROWS(Gares[Vers1]),Param!$B$2),"&",""),"$",""),"@","")=$I8,1,0))} -> 2 | H8: =IF(F8=G8,1,0) -> 1 | I8: =Gares[[#This Row],[Abv]] -> SCW | J8: =I9 -> BRW | K8: =I7 -> SXE | P8: =IF(Gares[[#This Row],[Vers1]]="",0,IF(_xlfn.XOR(ISERROR(MATCH(SUBSTITUTE(SUBSTITUTE(SUBSTITUTE(Gares[[#This Row],[Vers1]],"&",""),"$",""),"@",""),$I$2:$I7,0)),NOT(ISERROR(FIND("&",Gares[[#This Row],[Vers1]])))),2,1)) -> 2 | Q8: =IF(Gares[[#This Row],[Vers2]]="",0,IF(_xlfn.XOR(ISERROR(MATCH(SUBSTITUTE(SUBSTITUTE(SUBSTITUTE(Gares[[#This Row],[Vers2]],"&",""),"$",""),"@",""),$I$2:$I7,0)),NOT(ISERROR(FIND("&",Gares[[#This Row],[Vers2]])))),2,1)) -> 1 | R8: =IF(Gares[[#This Row],[Vers3]]="",0,IF(_xlfn.XOR(ISERROR(MATCH(SUBSTITUTE(SUBSTITUTE(SUBSTITUTE(Gares[[#This Row],[Vers3]],"&",""),"$",""),"@",""),$I$2:$I7,0)),NOT(ISERROR(FIND("&",Gares[[#This Row],[Vers3]])))),2,1)) -> 0 | S8: =IF(Gares[[#This Row],[Vers4]]="",0,IF(_xlfn.XOR(ISERROR(MATCH(SUBSTITUTE(SUBSTITUTE(SUBSTITUTE(Gares[[#This Row],[Vers4]],"&",""),"$",""),"@",""),$I$2:$I7,0)),NOT(ISERROR(FIND("&",Gares[[#This Row],[Vers4]])))),2,1)) -> 0 | T8: =IF(Gares[[#This Row],[Vers5]]="",0,IF(_xlfn.XOR(ISERROR(MATCH(SUBSTITUTE(SUBSTITUTE(SUBSTITUTE(Gares[[#This Row],[Vers5]],"&",""),"$",""),"@",""),$I$2:$I7,0)),NOT(ISERROR(FIND("&",Gares[[#This Row],[Vers5]])))),2,1)) -> 0 | U8: =IF(Gares[[#This Row],[Vers6]]="",0,IF(_xlfn.XOR(ISERROR(MATCH(SUBSTITUTE(SUBSTITUTE(SUBSTITUTE(Gares[[#This Row],[Vers6]],"&",""),"$",""),"@",""),$I$2:$I7,0)),NOT(ISERROR(FIND("&",Gares[[#This Row],[Vers6]])))),2,1)) -> 0 | V8: =IF(Gares[[#This Row],[SensDe1]]=0,0,IF(ISERROR(FIND("$",Gares[[#This Row],[Vers1]]))*ISERROR(FIND("@",Gares[[#This Row],[Vers1]])),Gares[[#This Row],[SensDe1]],3-Gares[[#This Row],[SensDe1]])) -> 2 | W8: =IF(Gares[[#This Row],[SensDe2]]=0,0,IF(ISERROR(FIND("$",Gares[[#This Row],[Vers2]]))*ISERROR(FIND("@",Gares[[#This Row],[Vers2]])),Gares[[#This Row],[SensDe2]],3-Gares[[#This Row],[SensDe2]])) -> 1 | X8: =IF(Gares[[#This Row],[SensDe3]]=0,0,IF(ISERROR(FIND("$",Gares[[#This Row],[Vers3]]))*ISERROR(FIND("@",Gares[[#This Row],[Vers3]])),Gares[[#This Row],[SensDe3]],3-Gares[[#This Row],[SensDe3]])) -> 0 | Y8: =IF(Gares[[#This Row],[SensDe4]]=0,0,IF(ISERROR(FIND("$",Gares[[#This Row],[Vers4]]))*ISERROR(FIND("@",Gares[[#This Row],[Vers4]])),Gares[[#This Row],[SensDe4]],3-Gares[[#This Row],[SensDe4]])) -> 0 | Z8: =IF(Gares[[#This Row],[SensDe5]]=0,0,IF(ISERROR(FIND("$",Gares[[#This Row],[Vers5]]))*ISERROR(FIND("@",Gares[[#This Row],[Vers5]])),Gares[[#This Row],[SensDe5]],3-Gares[[#This Row],[SensDe5]])) -> 0 | AA8: =IF(Gares[[#This Row],[SensDe6]]=0,0,IF(ISERROR(FIND("$",Gares[[#This Row],[Vers6]]))*ISERROR(FIND("@",Gares[[#This Row],[Vers6]])),Gares[[#This Row],[SensDe6]],3-Gares[[#This Row],[SensDe6]])) -> 0
A9: BRW | B9: Breuillet Village | F9: =COUNTA($J9:$N9) -> 2 | G9: {=SUM(IF(SUBSTITUTE(SUBSTITUTE(SUBSTITUTE(OFFSET($J$3,0,0,ROWS(Gares[Vers1]),Param!$B$2),"&",""),"$",""),"@","")=$I9,1,0))} -> 2 | H9: =IF(F9=G9,1,0) -> 1 | I9: =Gares[[#This Row],[Abv]] -> BRW | J9: =I10 -> BIH | K9: =I8 -> SCW | P9: =IF(Gares[[#This Row],[Vers1]]="",0,IF(_xlfn.XOR(ISERROR(MATCH(SUBSTITUTE(SUBSTITUTE(SUBSTITUTE(Gares[[#This Row],[Vers1]],"&",""),"$",""),"@",""),$I$2:$I8,0)),NOT(ISERROR(FIND("&",Gares[[#This Row],[Vers1]])))),2,1)) -> 2 | Q9: =IF(Gares[[#This Row],[Vers2]]="",0,IF(_xlfn.XOR(ISERROR(MATCH(SUBSTITUTE(SUBSTITUTE(SUBSTITUTE(Gares[[#This Row],[Vers2]],"&",""),"$",""),"@",""),$I$2:$I8,0)),NOT(ISERROR(FIND("&",Gares[[#This Row],[Vers2]])))),2,1)) -> 1 | R9: =IF(Gares[[#This Row],[Vers3]]="",0,IF(_xlfn.XOR(ISERROR(MATCH(SUBSTITUTE(SUBSTITUTE(SUBSTITUTE(Gares[[#This Row],[Vers3]],"&",""),"$",""),"@",""),$I$2:$I8,0)),NOT(ISERROR(FIND("&",Gares[[#This Row],[Vers3]])))),2,1)) -> 0 | S9: =IF(Gares[[#This Row],[Vers4]]="",0,IF(_xlfn.XOR(ISERROR(MATCH(SUBSTITUTE(SUBSTITUTE(SUBSTITUTE(Gares[[#This Row],[Vers4]],"&",""),"$",""),"@",""),$I$2:$I8,0)),NOT(ISERROR(FIND("&",Gares[[#This Row],[Vers4]])))),2,1)) -> 0 | T9: =IF(Gares[[#This Row],[Vers5]]="",0,IF(_xlfn.XOR(ISERROR(MATCH(SUBSTITUTE(SUBSTITUTE(SUBSTITUTE(Gares[[#This Row],[Vers5]],"&",""),"$",""),"@",""),$I$2:$I8,0)),NOT(ISERROR(FIND("&",Gares[[#This Row],[Vers5]])))),2,1)) -> 0 | U9: =IF(Gares[[#This Row],[Vers6]]="",0,IF(_xlfn.XOR(ISERROR(MATCH(SUBSTITUTE(SUBSTITUTE(SUBSTITUTE(Gares[[#This Row],[Vers6]],"&",""),"$",""),"@",""),$I$2:$I8,0)),NOT(ISERROR(FIND("&",Gares[[#This Row],[Vers6]])))),2,1)) -> 0 | V9: =IF(Gares[[#This Row],[SensDe1]]=0,0,IF(ISERROR(FIND("$",Gares[[#This Row],[Vers1]]))*ISERROR(FIND("@",Gares[[#This Row],[Vers1]])),Gares[[#This Row],[SensDe1]],3-Gares[[#This Row],[SensDe1]])) -> 2 | W9: =IF(Gares[[#This Row],[SensDe2]]=0,0,IF(ISERROR(FIND("$",Gares[[#This Row],[Vers2]]))*ISERROR(FIND("@",Gares[[#This Row],[Vers2]])),Gares[[#This Row],[SensDe2]],3-Gares[[#This Row],[SensDe2]])) -> 1 | X9: =IF(Gares[[#This Row],[SensDe3]]=0,0,IF(ISERROR(FIND("$",Gares[[#This Row],[Vers3]]))*ISERROR(FIND("@",Gares[[#This Row],[Vers3]])),Gares[[#This Row],[SensDe3]],3-Gares[[#This Row],[SensDe3]])) -> 0 | Y9: =IF(Gares[[#This Row],[SensDe4]]=0,0,IF(ISERROR(FIND("$",Gares[[#This Row],[Vers4]]))*ISERROR(FIND("@",Gares[[#This Row],[Vers4]])),Gares[[#This Row],[SensDe4]],3-Gares[[#This Row],[SensDe4]])) -> 0 | Z9: =IF(Gares[[#This Row],[SensDe5]]=0,0,IF(ISERROR(FIND("$",Gares[[#This Row],[Vers5]]))*ISERROR(FIND("@",Gares[[#This Row],[Vers5]])),Gares[[#This Row],[SensDe5]],3-Gares[[#This Row],[SensDe5]])) -> 0 | AA9: =IF(Gares[[#This Row],[SensDe6]]=0,0,IF(ISERROR(FIND("$",Gares[[#This Row],[Vers6]]))*ISERROR(FIND("@",Gares[[#This Row],[Vers6]])),Gares[[#This Row],[SensDe6]],3-Gares[[#This Row],[SensDe6]])) -> 0
A10: BIH | B10: Breuillet - Bruyères Le Châtel | F10: =COUNTA($J10:$N10) -> 2 | G10: {=SUM(IF(SUBSTITUTE(SUBSTITUTE(SUBSTITUTE(OFFSET($J$3,0,0,ROWS(Gares[Vers1]),Param!$B$2),"&",""),"$",""),"@","")=$I10,1,0))} -> 2 | H10: =IF(F10=G10,1,0) -> 1 | I10: =Gares[[#This Row],[Abv]] -> BIH | J10: =I11 -> ELY | K10: =I9 -> BRW | P10: =IF(Gares[[#This Row],[Vers1]]="",0,IF(_xlfn.XOR(ISERROR(MATCH(SUBSTITUTE(SUBSTITUTE(SUBSTITUTE(Gares[[#This Row],[Vers1]],"&",""),"$",""),"@",""),$I$2:$I9,0)),NOT(ISERROR(FIND("&",Gares[[#This Row],[Vers1]])))),2,1)) -> 2 | Q10: =IF(Gares[[#This Row],[Vers2]]="",0,IF(_xlfn.XOR(ISERROR(MATCH(SUBSTITUTE(SUBSTITUTE(SUBSTITUTE(Gares[[#This Row],[Vers2]],"&",""),"$",""),"@",""),$I$2:$I9,0)),NOT(ISERROR(FIND("&",Gares[[#This Row],[Vers2]])))),2,1)) -> 1 | R10: =IF(Gares[[#This Row],[Vers3]]="",0,IF(_xlfn.XOR(ISERROR(MATCH(SUBSTITUTE(SUBSTITUTE(SUBSTITUTE(Gares[[#This Row],[Vers3]],"&",""),"$",""),"@",""),$I$2:$I9,0)),NOT(ISERROR(FIND("&",Gares[[#This Row],[Vers3]])))),2,1)) -> 0 | S10: =IF(Gares[[#This Row],[Vers4]]="",0,IF(_xlfn.XOR(ISERROR(MATCH(SUBSTITUTE(SUBSTITUTE(SUBSTITUTE(Gares[[#This Row],[Vers4]],"&",""),"$",""),"@",""),$I$2:$I9,0)),NOT(ISERROR(FIND("&",Gares[[#This Row],[Vers4]])))),2,1)) -> 0 | T10: =IF(Gares[[#This Row],[Vers5]]="",0,IF(_xlfn.XOR(ISERROR(MATCH(SUBSTITUTE(SUBSTITUTE(SUBSTITUTE(Gares[[#This Row],[Vers5]],"&",""),"$",""),"@",""),$I$2:$I9,0)),NOT(ISERROR(FIND("&",Gares[[#This Row],[Vers5]])))),2,1)) -> 0 | U10: =IF(Gares[[#This Row],[Vers6]]="",0,IF(_xlfn.XOR(ISERROR(MATCH(SUBSTITUTE(SUBSTITUTE(SUBSTITUTE(Gares[[#This Row],[Vers6]],"&",""),"$",""),"@",""),$I$2:$I9,0)),NOT(ISERROR(FIND("&",Gares[[#This Row],[Vers6]])))),2,1)) -> 0 | V10: =IF(Gares[[#This Row],[SensDe1]]=0,0,IF(ISERROR(FIND("$",Gares[[#This Row],[Vers1]]))*ISERROR(FIND("@",Gares[[#This Row],[Vers1]])),Gares[[#This Row],[SensDe1]],3-Gares[[#This Row],[SensDe1]])) -> 2 | W10: =IF(Gares[[#This Row],[SensDe2]]=0,0,IF(ISERROR(FIND("$",Gares[[#This Row],[Vers2]]))*ISERROR(FIND("@",Gares[[#This Row],[Vers2]])),Gares[[#This Row],[SensDe2]],3-Gares[[#This Row],[SensDe2]])) -> 1 | X10: =IF(Gares[[#This Row],[SensDe3]]=0,0,IF(ISERROR(FIND("$",Gares[[#This Row],[Vers3]]))*ISERROR(FIND("@",Gares[[#This Row],[Vers3]])),Gares[[#This Row],[SensDe3]],3-Gares[[#This Row],[SensDe3]])) -> 0 | Y10: =IF(Gares[[#This Row],[SensDe4]]=0,0,IF(ISERROR(FIND("$",Gares[[#This Row],[Vers4]]))*ISERROR(FIND("@",Gares[[#This Row],[Vers4]])),Gares[[#This Row],[SensDe4]],3-Gares[[#This Row],[SensDe4]])) -> 0 | Z10: =IF(Gares[[#This Row],[SensDe5]]=0,0,IF(ISERROR(FIND("$",Gares[[#This Row],[Vers5]]))*ISERROR(FIND("@",Gares[[#This Row],[Vers5]])),Gares[[#This Row],[SensDe5]],3-Gares[[#This Row],[SensDe5]])) -> 0 | AA10: =IF(Gares[[#This Row],[SensDe6]]=0,0,IF(ISERROR(FIND("$",Gares[[#This Row],[Vers6]]))*ISERROR(FIND("@",Gares[[#This Row],[Vers6]])),Gares[[#This Row],[SensDe6]],3-Gares[[#This Row],[SensDe6]])) -> 0
A11: ELY | B11: Egly | F11: =COUNTA($J11:$N11) -> 2 | G11: {=SUM(IF(SUBSTITUTE(SUBSTITUTE(SUBSTITUTE(OFFSET($J$3,0,0,ROWS(Gares[Vers1]),Param!$B$2),"&",""),"$",""),"@","")=$I11,1,0))} -> 2 | H11: =IF(F11=G11,1,0) -> 1 | I11: =Gares[[#This Row],[Abv]] -> ELY | J11: =I12 -> ARP | K11: =I10 -> BIH | P11: =IF(Gares[[#This Row],[Vers1]]="",0,IF(_xlfn.XOR(ISERROR(MATCH(SUBSTITUTE(SUBSTITUTE(SUBSTITUTE(Gares[[#This Row],[Vers1]],"&",""),"$",""),"@",""),$I$2:$I10,0)),NOT(ISERROR(FIND("&",Gares[[#This Row],[Vers1]])))),2,1)) -> 2 | Q11: =IF(Gares[[#This Row],[Vers2]]="",0,IF(_xlfn.XOR(ISERROR(MATCH(SUBSTITUTE(SUBSTITUTE(SUBSTITUTE(Gares[[#This Row],[Vers2]],"&",""),"$",""),"@",""),$I$2:$I10,0)),NOT(ISERROR(FIND("&",Gares[[#This Row],[Vers2]])))),2,1)) -> 1 | R11: =IF(Gares[[#This Row],[Vers3]]="",0,IF(_xlfn.XOR(ISERROR(MATCH(SUBSTITUTE(SUBSTITUTE(SUBSTITUTE(Gares[[#This Row],[Vers3]],"&",""),"$",""),"@",""),$I$2:$I10,0)),NOT(ISERROR(FIND("&",Gares[[#This Row],[Vers3]])))),2,1)) -> 0 | S11: =IF(Gares[[#This Row],[Vers4]]="",0,IF(_xlfn.XOR(ISERROR(MATCH(SUBSTITUTE(SUBSTITUTE(SUBSTITUTE(Gares[[#This Row],[Vers4]],"&",""),"$",""),"@",""),$I$2:$I10,0)),NOT(ISERROR(FIND("&",Gares[[#This Row],[Vers4]])))),2,1)) -> 0 | T11: =IF(Gares[[#This Row],[Vers5]]="",0,IF(_xlfn.XOR(ISERROR(MATCH(SUBSTITUTE(SUBSTITUTE(SUBSTITUTE(Gares[[#This Row],[Vers5]],"&",""),"$",""),"@",""),$I$2:$I10,0)),NOT(ISERROR(FIND("&",Gares[[#This Row],[Vers5]])))),2,1)) -> 0 | U11: =IF(Gares[[#This Row],[Vers6]]="",0,IF(_xlfn.XOR(ISERROR(MATCH(SUBSTITUTE(SUBSTITUTE(SUBSTITUTE(Gares[[#This Row],[Vers6]],"&",""),"$",""),"@",""),$I$2:$I10,0)),NOT(ISERROR(FIND("&",Gares[[#This Row],[Vers6]])))),2,1)) -> 0 | V11: =IF(Gares[[#This Row],[SensDe1]]=0,0,IF(ISERROR(FIND("$",Gares[[#This Row],[Vers1]]))*ISERROR(FIND("@",Gares[[#This Row],[Vers1]])),Gares[[#This Row],[SensDe1]],3-Gares[[#This Row],[SensDe1]])) -> 2 | W11: =IF(Gares[[#This Row],[SensDe2]]=0,0,IF(ISERROR(FIND("$",Gares[[#This Row],[Vers2]]))*ISERROR(FIND("@",Gares[[#This Row],[Vers2]])),Gares[[#This Row],[SensDe2]],3-Gares[[#This Row],[SensDe2]])) -> 1 | X11: =IF(Gares[[#This Row],[SensDe3]]=0,0,IF(ISERROR(FIND("$",Gares[[#This Row],[Vers3]]))*ISERROR(FIND("@",Gares[[#This Row],[Vers3]])),Gares[[#This Row],[SensDe3]],3-Gares[[#This Row],[SensDe3]])) -> 0 | Y11: =IF(Gares[[#This Row],[SensDe4]]=0,0,IF(ISERROR(FIND("$",Gares[[#This Row],[Vers4]]))*ISERROR(FIND("@",Gares[[#This Row],[Vers4]])),Gares[[#This Row],[SensDe4]],3-Gares[[#This Row],[SensDe4]])) -> 0 | Z11: =IF(Gares[[#This Row],[SensDe5]]=0,0,IF(ISERROR(FIND("$",Gares[[#This Row],[Vers5]]))*ISERROR(FIND("@",Gares[[#This Row],[Vers5]])),Gares[[#This Row],[SensDe5]],3-Gares[[#This Row],[SensDe5]])) -> 0 | AA11: =IF(Gares[[#This Row],[SensDe6]]=0,0,IF(ISERROR(FIND("$",Gares[[#This Row],[Vers6]]))*ISERROR(FIND("@",Gares[[#This Row],[Vers6]])),Gares[[#This Row],[SensDe6]],3-Gares[[#This Row],[SensDe6]])) -> 0
A12: ARP | B12: Arpajon | F12: =COUNTA($J12:$N12) -> 2 | G12: {=SUM(IF(SUBSTITUTE(SUBSTITUTE(SUBSTITUTE(OFFSET($J$3,0,0,ROWS(Gares[Vers1]),Param!$B$2),"&",""),"$",""),"@","")=$I12,1,0))} -> 2 | H12: =IF(F12=G12,1,0) -> 1 | I12: =Gares[[#This Row],[Abv]] -> ARP | J12: =I13 -> NG | K12: =I11 -> ELY | P12: =IF(Gares[[#This Row],[Vers1]]="",0,IF(_xlfn.XOR(ISERROR(MATCH(SUBSTITUTE(SUBSTITUTE(SUBSTITUTE(Gares[[#This Row],[Vers1]],"&",""),"$",""),"@",""),$I$2:$I11,0)),NOT(ISERROR(FIND("&",Gares[[#This Row],[Vers1]])))),2,1)) -> 2 | Q12: =IF(Gares[[#This Row],[Vers2]]="",0,IF(_xlfn.XOR(ISERROR(MATCH(SUBSTITUTE(SUBSTITUTE(SUBSTITUTE(Gares[[#This Row],[Vers2]],"&",""),"$",""),"@",""),$I$2:$I11,0)),NOT(ISERROR(FIND("&",Gares[[#This Row],[Vers2]])))),2,1)) -> 1 | R12: =IF(Gares[[#This Row],[Vers3]]="",0,IF(_xlfn.XOR(ISERROR(MATCH(SUBSTITUTE(SUBSTITUTE(SUBSTITUTE(Gares[[#This Row],[Vers3]],"&",""),"$",""),"@",""),$I$2:$I11,0)),NOT(ISERROR(FIND("&",Gares[[#This Row],[Vers3]])))),2,1)) -> 0 | S12: =IF(Gares[[#This Row],[Vers4]]="",0,IF(_xlfn.XOR(ISERROR(MATCH(SUBSTITUTE(SUBSTITUTE(SUBSTITUTE(Gares[[#This Row],[Vers4]],"&",""),"$",""),"@",""),$I$2:$I11,0)),NOT(ISERROR(FIND("&",Gares[[#This Row],[Vers4]])))),2,1)) -> 0 | T12: =IF(Gares[[#This Row],[Vers5]]="",0,IF(_xlfn.XOR(ISERROR(MATCH(SUBSTITUTE(SUBSTITUTE(SUBSTITUTE(Gares[[#This Row],[Vers5]],"&",""),"$",""),"@",""),$I$2:$I11,0)),NOT(ISERROR(FIND("&",Gares[[#This Row],[Vers5]])))),2,1)) -> 0 | U12: =IF(Gares[[#This Row],[Vers6]]="",0,IF(_xlfn.XOR(ISERROR(MATCH(SUBSTITUTE(SUBSTITUTE(SUBSTITUTE(Gares[[#This Row],[Vers6]],"&",""),"$",""),"@",""),$I$2:$I11,0)),NOT(ISERROR(FIND("&",Gares[[#This Row],[Vers6]])))),2,1)) -> 0 | V12: =IF(Gares[[#This Row],[SensDe1]]=0,0,IF(ISERROR(FIND("$",Gares[[#This Row],[Vers1]]))*ISERROR(FIND("@",Gares[[#This Row],[Vers1]])),Gares[[#This Row],[SensDe1]],3-Gares[[#This Row],[SensDe1]])) -> 2 | W12: =IF(Gares[[#This Row],[SensDe2]]=0,0,IF(ISERROR(FIND("$",Gares[[#This Row],[Vers2]]))*ISERROR(FIND("@",Gares[[#This Row],[Vers2]])),Gares[[#This Row],[SensDe2]],3-Gares[[#This Row],[SensDe2]])) -> 1 | X12: =IF(Gares[[#This Row],[SensDe3]]=0,0,IF(ISERROR(FIND("$",Gares[[#This Row],[Vers3]]))*ISERROR(FIND("@",Gares[[#This Row],[Vers3]])),Gares[[#This Row],[SensDe3]],3-Gares[[#This Row],[SensDe3]])) -> 0 | Y12: =IF(Gares[[#This Row],[SensDe4]]=0,0,IF(ISERROR(FIND("$",Gares[[#This Row],[Vers4]]))*ISERROR(FIND("@",Gares[[#This Row],[Vers4]])),Gares[[#This Row],[SensDe4]],3-Gares[[#This Row],[SensDe4]])) -> 0 | Z12: =IF(Gares[[#This Row],[SensDe5]]=0,0,IF(ISERROR(FIND("$",Gares[[#This Row],[Vers5]]))*ISERROR(FIND("@",Gares[[#This Row],[Vers5]])),Gares[[#This Row],[SensDe5]],3-Gares[[#This Row],[SensDe5]])) -> 0 | AA12: =IF(Gares[[#This Row],[SensDe6]]=0,0,IF(ISERROR(FIND("$",Gares[[#This Row],[Vers6]]))*ISERROR(FIND("@",Gares[[#This Row],[Vers6]])),Gares[[#This Row],[SensDe6]],3-Gares[[#This Row],[SensDe6]])) -> 0
A13: NG | B13: La Norville Saint-Germain-lès-Arpajon | F13: =COUNTA($J13:$N13) -> 3 | G13: {=SUM(IF(SUBSTITUTE(SUBSTITUTE(SUBSTITUTE(OFFSET($J$3,0,0,ROWS(Gares[Vers1]),Param!$B$2),"&",""),"$",""),"@","")=$I13,1,0))} -> 3 | H13: =IF(F13=G13,1,0) -> 1 | I13: =Gares[[#This Row],[Abv]] -> NG | J13: BY | K13: =I12 -> ARP | L13: BY-GB | P13: =IF(Gares[[#This Row],[Vers1]]="",0,IF(_xlfn.XOR(ISERROR(MATCH(SUBSTITUTE(SUBSTITUTE(SUBSTITUTE(Gares[[#This Row],[Vers1]],"&",""),"$",""),"@",""),$I$2:$I12,0)),NOT(ISERROR(FIND("&",Gares[[#This Row],[Vers1]])))),2,1)) -> 2 | Q13: =IF(Gares[[#This Row],[Vers2]]="",0,IF(_xlfn.XOR(ISERROR(MATCH(SUBSTITUTE(SUBSTITUTE(SUBSTITUTE(Gares[[#This Row],[Vers2]],"&",""),"$",""),"@",""),$I$2:$I12,0)),NOT(ISERROR(FIND("&",Gares[[#This Row],[Vers2]])))),2,1)) -> 1 | R13: =IF(Gares[[#This Row],[Vers3]]="",0,IF(_xlfn.XOR(ISERROR(MATCH(SUBSTITUTE(SUBSTITUTE(SUBSTITUTE(Gares[[#This Row],[Vers3]],"&",""),"$",""),"@",""),$I$2:$I12,0)),NOT(ISERROR(FIND("&",Gares[[#This Row],[Vers3]])))),2,1)) -> 2 | S13: =IF(Gares[[#This Row],[Vers4]]="",0,IF(_xlfn.XOR(ISERROR(MATCH(SUBSTITUTE(SUBSTITUTE(SUBSTITUTE(Gares[[#This Row],[Vers4]],"&",""),"$",""),"@",""),$I$2:$I12,0)),NOT(ISERROR(FIND("&",Gares[[#This Row],[Vers4]])))),2,1)) -> 0 | T13: =IF(Gares[[#This Row],[Vers5]]="",0,IF(_xlfn.XOR(ISERROR(MATCH(SUBSTITUTE(SUBSTITUTE(SUBSTITUTE(Gares[[#This Row],[Vers5]],"&",""),"$",""),"@",""),$I$2:$I12,0)),NOT(ISERROR(FIND("&",Gares[[#This Row],[Vers5]])))),2,1)) -> 0 | U13: =IF(Gares[[#This Row],[Vers6]]="",0,IF(_xlfn.XOR(ISERROR(MATCH(SUBSTITUTE(SUBSTITUTE(SUBSTITUTE(Gares[[#This Row],[Vers6]],"&",""),"$",""),"@",""),$I$2:$I12,0)),NOT(ISERROR(FIND("&",Gares[[#This Row],[Vers6]])))),2,1)) -> 0 | V13: =IF(Gares[[#This Row],[SensDe1]]=0,0,IF(ISERROR(FIND("$",Gares[[#This Row],[Vers1]]))*ISERROR(FIND("@",Gares[[#This Row],[Vers1]])),Gares[[#This Row],[SensDe1]],3-Gares[[#This Row],[SensDe1]])) -> 2 | W13: =IF(Gares[[#This Row],[SensDe2]]=0,0,IF(ISERROR(FIND("$",Gares[[#This Row],[Vers2]]))*ISERROR(FIND("@",Gares[[#This Row],[Vers2]])),Gares[[#This Row],[SensDe2]],3-Gares[[#This Row],[SensDe2]])) -> 1 | X13: =IF(Gares[[#This Row],[SensDe3]]=0,0,IF(ISERROR(FIND("$",Gares[[#This Row],[Vers3]]))*ISERROR(FIND("@",Gares[[#This Row],[Vers3]])),Gares[[#This Row],[SensDe3]],3-Gares[[#This Row],[SensDe3]])) -> 2 | Y13: =IF(Gares[[#This Row],[SensDe4]]=0,0,IF(ISERROR(FIND("$",Gares[[#This Row],[Vers4]]))*ISERROR(FIND("@",Gares[[#This Row],[Vers4]])),Gares[[#This Row],[SensDe4]],3-Gares[[#This Row],[SensDe4]])) -> 0 | Z13: =IF(Gares[[#This Row],[SensDe5]]=0,0,IF(ISERROR(FIND("$",Gares[[#This Row],[Vers5]]))*ISERROR(FIND("@",Gares[[#This Row],[Vers5]])),Gares[[#This Row],[SensDe5]],3-Gares[[#This Row],[SensDe5]])) -> 0 | AA13: =IF(Gares[[#This Row],[SensDe6]]=0,0,IF(ISERROR(FIND("$",Gares[[#This Row],[Vers6]]))*ISERROR(FIND("@",Gares[[#This Row],[Vers6]])),Gares[[#This Row],[SensDe6]],3-Gares[[#This Row],[SensDe6]])) -> 0
A14: SME | B14: Saint-Martin d'Etampes | D14: I | F14: =COUNTA($J14:$N14) -> 1 | G14: {=SUM(IF(SUBSTITUTE(SUBSTITUTE(SUBSTITUTE(OFFSET($J$3,0,0,ROWS(Gares[Vers1]),Param!$B$2),"&",""),"$",""),"@","")=$I14,1,0))} -> 1 | H14: =IF(F14=G14,1,0) -> 1 | I14: =Gares[[#This Row],[Abv]] -> SME | J14: =I15 -> ETP | P14: =IF(Gares[[#This Row],[Vers1]]="",0,IF(_xlfn.XOR(ISERROR(MATCH(SUBSTITUTE(SUBSTITUTE(SUBSTITUTE(Gares[[#This Row],[Vers1]],"&",""),"$",""),"@",""),$I$2:$I13,0)),NOT(ISERROR(FIND("&",Gares[[#This Row],[Vers1]])))),2,1)) -> 2 | Q14: =IF(Gares[[#This Row],[Vers2]]="",0,IF(_xlfn.XOR(ISERROR(MATCH(SUBSTITUTE(SUBSTITUTE(SUBSTITUTE(Gares[[#This Row],[Vers2]],"&",""),"$",""),"@",""),$I$2:$I13,0)),NOT(ISERROR(FIND("&",Gares[[#This Row],[Vers2]])))),2,1)) -> 0 | R14: =IF(Gares[[#This Row],[Vers3]]="",0,IF(_xlfn.XOR(ISERROR(MATCH(SUBSTITUTE(SUBSTITUTE(SUBSTITUTE(Gares[[#This Row],[Vers3]],"&",""),"$",""),"@",""),$I$2:$I13,0)),NOT(ISERROR(FIND("&",Gares[[#This Row],[Vers3]])))),2,1)) -> 0 | S14: =IF(Gares[[#This Row],[Vers4]]="",0,IF(_xlfn.XOR(ISERROR(MATCH(SUBSTITUTE(SUBSTITUTE(SUBSTITUTE(Gares[[#This Row],[Vers4]],"&",""),"$",""),"@",""),$I$2:$I13,0)),NOT(ISERROR(FIND("&",Gares[[#This Row],[Vers4]])))),2,1)) -> 0 | T14: =IF(Gares[[#This Row],[Vers5]]="",0,IF(_xlfn.XOR(ISERROR(MATCH(SUBSTITUTE(SUBSTITUTE(SUBSTITUTE(Gares[[#This Row],[Vers5]],"&",""),"$",""),"@",""),$I$2:$I13,0)),NOT(ISERROR(FIND("&",Gares[[#This Row],[Vers5]])))),2,1)) -> 0 | U14: =IF(Gares[[#This Row],[Vers6]]="",0,IF(_xlfn.XOR(ISERROR(MATCH(SUBSTITUTE(SUBSTITUTE(SUBSTITUTE(Gares[[#This Row],[Vers6]],"&",""),"$",""),"@",""),$I$2:$I13,0)),NOT(ISERROR(FIND("&",Gares[[#This Row],[Vers6]])))),2,1)) -> 0 | V14: =IF(Gares[[#This Row],[SensDe1]]=0,0,IF(ISERROR(FIND("$",Gares[[#This Row],[Vers1]]))*ISERROR(FIND("@",Gares[[#This Row],[Vers1]])),Gares[[#This Row],[SensDe1]],3-Gares[[#This Row],[SensDe1]])) -> 2 | W14: =IF(Gares[[#This Row],[SensDe2]]=0,0,IF(ISERROR(FIND("$",Gares[[#This Row],[Vers2]]))*ISERROR(FIND("@",Gares[[#This Row],[Vers2]])),Gares[[#This Row],[SensDe2]],3-Gares[[#This Row],[SensDe2]])) -> 0 | X14: =IF(Gares[[#This Row],[SensDe3]]=0,0,IF(ISERROR(FIND("$",Gares[[#This Row],[Vers3]]))*ISERROR(FIND("@",Gares[[#This Row],[Vers3]])),Gares[[#This Row],[SensDe3]],3-Gares[[#This Row],[SensDe3]])) -> 0 | Y14: =IF(Gares[[#This Row],[SensDe4]]=0,0,IF(ISERROR(FIND("$",Gares[[#This Row],[Vers4]]))*ISERROR(FIND("@",Gares[[#This Row],[Vers4]])),Gares[[#This Row],[SensDe4]],3-Gares[[#This Row],[SensDe4]])) -> 0 | Z14: =IF(Gares[[#This Row],[SensDe5]]=0,0,IF(ISERROR(FIND("$",Gares[[#This Row],[Vers5]]))*ISERROR(FIND("@",Gares[[#This Row],[Vers5]])),Gares[[#This Row],[SensDe5]],3-Gares[[#This Row],[SensDe5]])) -> 0 | AA14: =IF(Gares[[#This Row],[SensDe6]]=0,0,IF(ISERROR(FIND("$",Gares[[#This Row],[Vers6]]))*ISERROR(FIND("@",Gares[[#This Row],[Vers6]])),Gares[[#This Row],[SensDe6]],3-Gares[[#This Row],[SensDe6]])) -> 0
A15: ETP | B15: Etampes | D15: I | F15: =COUNTA($J15:$N15) -> 3 | G15: {=SUM(IF(SUBSTITUTE(SUBSTITUTE(SUBSTITUTE(OFFSET($J$3,0,0,ROWS(Gares[Vers1]),Param!$B$2),"&",""),"$",""),"@","")=$I15,1,0))} -> 3 | H15: =IF(F15=G15,1,0) -> 1 | I15: =Gares[[#This Row],[Abv]] -> ETP | J15: ETY | K15: SME | L15: ETP-GM | P15: =IF(Gares[[#This Row],[Vers1]]="",0,IF(_xlfn.XOR(ISERROR(MATCH(SUBSTITUTE(SUBSTITUTE(SUBSTITUTE(Gares[[#This Row],[Vers1]],"&",""),"$",""),"@",""),$I$2:$I14,0)),NOT(ISERROR(FIND("&",Gares[[#This Row],[Vers1]])))),2,1)) -> 2 | Q15: =IF(Gares[[#This Row],[Vers2]]="",0,IF(_xlfn.XOR(ISERROR(MATCH(SUBSTITUTE(SUBSTITUTE(SUBSTITUTE(Gares[[#This Row],[Vers2]],"&",""),"$",""),"@",""),$I$2:$I14,0)),NOT(ISERROR(FIND("&",Gares[[#This Row],[Vers2]])))),2,1)) -> 1 | R15: =IF(Gares[[#This Row],[Vers3]]="",0,IF(_xlfn.XOR(ISERROR(MATCH(SUBSTITUTE(SUBSTITUTE(SUBSTITUTE(Gares[[#This Row],[Vers3]],"&",""),"$",""),"@",""),$I$2:$I14,0)),NOT(ISERROR(FIND("&",Gares[[#This Row],[Vers3]])))),2,1)) -> 2 | S15: =IF(Gares[[#This Row],[Vers4]]="",0,IF(_xlfn.XOR(ISERROR(MATCH(SUBSTITUTE(SUBSTITUTE(SUBSTITUTE(Gares[[#This Row],[Vers4]],"&",""),"$",""),"@",""),$I$2:$I14,0)),NOT(ISERROR(FIND("&",Gares[[#This Row],[Vers4]])))),2,1)) -> 0 | T15: =IF(Gares[[#This Row],[Vers5]]="",0,IF(_xlfn.XOR(ISERROR(MATCH(SUBSTITUTE(SUBSTITUTE(SUBSTITUTE(Gares[[#This Row],[Vers5]],"&",""),"$",""),"@",""),$I$2:$I14,0)),NOT(ISERROR(FIND("&",Gares[[#This Row],[Vers5]])))),2,1)) -> 0 | U15: =IF(Gares[[#This Row],[Vers6]]="",0,IF(_xlfn.XOR(ISERROR(MATCH(SUBSTITUTE(SUBSTITUTE(SUBSTITUTE(Gares[[#This Row],[Vers6]],"&",""),"$",""),"@",""),$I$2:$I14,0)),NOT(ISERROR(FIND("&",Gares[[#This Row],[Vers6]])))),2,1)) -> 0 | V15: =IF(Gares[[#This Row],[SensDe1]]=0,0,IF(ISERROR(FIND("$",Gares[[#This Row],[Vers1]]))*ISERROR(FIND("@",Gares[[#This Row],[Vers1]])),Gares[[#This Row],[SensDe1]],3-Gares[[#This Row],[SensDe1]])) -> 2 | W15: =IF(Gares[[#This Row],[SensDe2]]=0,0,IF(ISERROR(FIND("$",Gares[[#This Row],[Vers2]]))*ISERROR(FIND("@",Gares[[#This Row],[Vers2]])),Gares[[#This Row],[SensDe2]],3-Gares[[#This Row],[SensDe2]])) -> 1 | X15: =IF(Gares[[#This Row],[SensDe3]]=0,0,IF(ISERROR(FIND("$",Gares[[#This Row],[Vers3]]))*ISERROR(FIND("@",Gares[[#This Row],[Vers3]])),Gares[[#This Row],[SensDe3]],3-Gares[[#This Row],[SensDe3]])) -> 2 | Y15: =IF(Gares[[#This Row],[SensDe4]]=0,0,IF(ISERROR(FIND("$",Gares[[#This Row],[Vers4]]))*ISERROR(FIND("@",Gares[[#This Row],[Vers4]])),Gares[[#This Row],[SensDe4]],3-Gares[[#This Row],[SensDe4]])) -> 0 | Z15: =IF(Gares[[#This Row],[SensDe5]]=0,0,IF(ISERROR(FIND("$",Gares[[#This Row],[Vers5]]))*ISERROR(FIND("@",Gares[[#This Row],[Vers5]])),Gares[[#This Row],[SensDe5]],3-Gares[[#This Row],[SensDe5]])) -> 0 | AA15: =IF(Gares[[#This Row],[SensDe6]]=0,0,IF(ISERROR(FIND("$",Gares[[#This Row],[Vers6]]))*ISERROR(FIND("@",Gares[[#This Row],[Vers6]])),Gares[[#This Row],[SensDe6]],3-Gares[[#This Row],[SensDe6]])) -> 0
A16: ETP-GM | B16: Etampes - Garages | D16: IP | F16: =COUNTA($J16:$N16) -> 2 | G16: {=SUM(IF(SUBSTITUTE(SUBSTITUTE(SUBSTITUTE(OFFSET($J$3,0,0,ROWS(Gares[Vers1]),Param!$B$2),"&",""),"$",""),"@","")=$I16,1,0))} -> 2 | H16: =IF(F16=G16,1,0) -> 1 | I16: =Gares[[#This Row],[Abv]] -> ETP-GM | J16: =I17 -> ETY | K16: ETP | P16: =IF(Gares[[#This Row],[Vers1]]="",0,IF(_xlfn.XOR(ISERROR(MATCH(SUBSTITUTE(SUBSTITUTE(SUBSTITUTE(Gares[[#This Row],[Vers1]],"&",""),"$",""),"@",""),$I$2:$I15,0)),NOT(ISERROR(FIND("&",Gares[[#This Row],[Vers1]])))),2,1)) -> 2 | Q16: =IF(Gares[[#This Row],[Vers2]]="",0,IF(_xlfn.XOR(ISERROR(MATCH(SUBSTITUTE(SUBSTITUTE(SUBSTITUTE(Gares[[#This Row],[Vers2]],"&",""),"$",""),"@",""),$I$2:$I15,0)),NOT(ISERROR(FIND("&",Gares[[#This Row],[Vers2]])))),2,1)) -> 1 | R16: =IF(Gares[[#This Row],[Vers3]]="",0,IF(_xlfn.XOR(ISERROR(MATCH(SUBSTITUTE(SUBSTITUTE(SUBSTITUTE(Gares[[#This Row],[Vers3]],"&",""),"$",""),"@",""),$I$2:$I15,0)),NOT(ISERROR(FIND("&",Gares[[#This Row],[Vers3]])))),2,1)) -> 0 | S16: =IF(Gares[[#This Row],[Vers4]]="",0,IF(_xlfn.XOR(ISERROR(MATCH(SUBSTITUTE(SUBSTITUTE(SUBSTITUTE(Gares[[#This Row],[Vers4]],"&",""),"$",""),"@",""),$I$2:$I15,0)),NOT(ISERROR(FIND("&",Gares[[#This Row],[Vers4]])))),2,1)) -> 0 | T16: =IF(Gares[[#This Row],[Vers5]]="",0,IF(_xlfn.XOR(ISERROR(MATCH(SUBSTITUTE(SUBSTITUTE(SUBSTITUTE(Gares[[#This Row],[Vers5]],"&",""),"$",""),"@",""),$I$2:$I15,0)),NOT(ISERROR(FIND("&",Gares[[#This Row],[Vers5]])))),2,1)) -> 0 | U16: =IF(Gares[[#This Row],[Vers6]]="",0,IF(_xlfn.XOR(ISERROR(MATCH(SUBSTITUTE(SUBSTITUTE(SUBSTITUTE(Gares[[#This Row],[Vers6]],"&",""),"$",""),"@",""),$I$2:$I15,0)),NOT(ISERROR(FIND("&",Gares[[#This Row],[Vers6]])))),2,1)) -> 0 | V16: =IF(Gares[[#This Row],[SensDe1]]=0,0,IF(ISERROR(FIND("$",Gares[[#This Row],[Vers1]]))*ISERROR(FIND("@",Gares[[#This Row],[Vers1]])),Gares[[#This Row],[SensDe1]],3-Gares[[#This Row],[SensDe1]])) -> 2 | W16: =IF(Gares[[#This Row],[SensDe2]]=0,0,IF(ISERROR(FIND("$",Gares[[#This Row],[Vers2]]))*ISERROR(FIND("@",Gares[[#This Row],[Vers2]])),Gares[[#This Row],[SensDe2]],3-Gares[[#This Row],[SensDe2]])) -> 1 | X16: =IF(Gares[[#This Row],[SensDe3]]=0,0,IF(ISERROR(FIND("$",Gares[[#This Row],[Vers3]]))*ISERROR(FIND("@",Gares[[#This Row],[Vers3]])),Gares[[#This Row],[SensDe3]],3-Gares[[#This Row],[SensDe3]])) -> 0 | Y16: =IF(Gares[[#This Row],[SensDe4]]=0,0,IF(ISERROR(FIND("$",Gares[[#This Row],[Vers4]]))*ISERROR(FIND("@",Gares[[#This Row],[Vers4]])),Gares[[#This Row],[SensDe4]],3-Gares[[#This Row],[SensDe4]])) -> 0 | Z16: =IF(Gares[[#This Row],[SensDe5]]=0,0,IF(ISERROR(FIND("$",Gares[[#This Row],[Vers5]]))*ISERROR(FIND("@",Gares[[#This Row],[Vers5]])),Gares[[#This Row],[SensDe5]],3-Gares[[#This Row],[SensDe5]])) -> 0 | AA16: =IF(Gares[[#This Row],[SensDe6]]=0,0,IF(ISERROR(FIND("$",Gares[[#This Row],[Vers6]]))*ISERROR(FIND("@",Gares[[#This Row],[Vers6]])),Gares[[#This Row],[SensDe6]],3-Gares[[#This Row],[SensDe6]])) -> 0
A17: ETY | B17: Etréchy | F17: =COUNTA($J17:$N17) -> 3 | G17: {=SUM(IF(SUBSTITUTE(SUBSTITUTE(SUBSTITUTE(OFFSET($J$3,0,0,ROWS(Gares[Vers1]),Param!$B$2),"&",""),"$",""),"@","")=$I17,1,0))} -> 3 | H17: =IF(F17=G17,1,0) -> 1 | I17: =Gares[[#This Row],[Abv]] -> ETY | J17: =I18 -> CHK | K17: ETP | L17: ETP-GM | P17: =IF(Gares[[#This Row],[Vers1]]="",0,IF(_xlfn.XOR(ISERROR(MATCH(SUBSTITUTE(SUBSTITUTE(SUBSTITUTE(Gares[[#This Row],[Vers1]],"&",""),"$",""),"@",""),$I$2:$I16,0)),NOT(ISERROR(FIND("&",Gares[[#This Row],[Vers1]])))),2,1)) -> 2 | Q17: =IF(Gares[[#This Row],[Vers2]]="",0,IF(_xlfn.XOR(ISERROR(MATCH(SUBSTITUTE(SUBSTITUTE(SUBSTITUTE(Gares[[#This Row],[Vers2]],"&",""),"$",""),"@",""),$I$2:$I16,0)),NOT(ISERROR(FIND("&",Gares[[#This Row],[Vers2]])))),2,1)) -> 1 | R17: =IF(Gares[[#This Row],[Vers3]]="",0,IF(_xlfn.XOR(ISERROR(MATCH(SUBSTITUTE(SUBSTITUTE(SUBSTITUTE(Gares[[#This Row],[Vers3]],"&",""),"$",""),"@",""),$I$2:$I16,0)),NOT(ISERROR(FIND("&",Gares[[#This Row],[Vers3]])))),2,1)) -> 1 | S17: =IF(Gares[[#This Row],[Vers4]]="",0,IF(_xlfn.XOR(ISERROR(MATCH(SUBSTITUTE(SUBSTITUTE(SUBSTITUTE(Gares[[#This Row],[Vers4]],"&",""),"$",""),"@",""),$I$2:$I16,0)),NOT(ISERROR(FIND("&",Gares[[#This Row],[Vers4]])))),2,1)) -> 0 | T17: =IF(Gares[[#This Row],[Vers5]]="",0,IF(_xlfn.XOR(ISERROR(MATCH(SUBSTITUTE(SUBSTITUTE(SUBSTITUTE(Gares[[#This Row],[Vers5]],"&",""),"$",""),"@",""),$I$2:$I16,0)),NOT(ISERROR(FIND("&",Gares[[#This Row],[Vers5]])))),2,1)) -> 0 | U17: =IF(Gares[[#This Row],[Vers6]]="",0,IF(_xlfn.XOR(ISERROR(MATCH(SUBSTITUTE(SUBSTITUTE(SUBSTITUTE(Gares[[#This Row],[Vers6]],"&",""),"$",""),"@",""),$I$2:$I16,0)),NOT(ISERROR(FIND("&",Gares[[#This Row],[Vers6]])))),2,1)) -> 0 | V17: =IF(Gares[[#This Row],[SensDe1]]=0,0,IF(ISERROR(FIND("$",Gares[[#This Row],[Vers1]]))*ISERROR(FIND("@",Gares[[#This Row],[Vers1]])),Gares[[#This Row],[SensDe1]],3-Gares[[#This Row],[SensDe1]])) -> 2 | W17: =IF(Gares[[#This Row],[SensDe2]]=0,0,IF(ISERROR(FIND("$",Gares[[#This Row],[Vers2]]))*ISERROR(FIND("@",Gares[[#This Row],[Vers2]])),Gares[[#This Row],[SensDe2]],3-Gares[[#This Row],[SensDe2]])) -> 1 | X17: =IF(Gares[[#This Row],[SensDe3]]=0,0,IF(ISERROR(FIND("$",Gares[[#This Row],[Vers3]]))*ISERROR(FIND("@",Gares[[#This Row],[Vers3]])),Gares[[#This Row],[SensDe3]],3-Gares[[#This Row],[SensDe3]])) -> 1 | Y17: =IF(Gares[[#This Row],[SensDe4]]=0,0,IF(ISERROR(FIND("$",Gares[[#This Row],[Vers4]]))*ISERROR(FIND("@",Gares[[#This Row],[Vers4]])),Gares[[#This Row],[SensDe4]],3-Gares[[#This Row],[SensDe4]])) -> 0 | Z17: =IF(Gares[[#This Row],[SensDe5]]=0,0,IF(ISERROR(FIND("$",Gares[[#This Row],[Vers5]]))*ISERROR(FIND("@",Gares[[#This Row],[Vers5]])),Gares[[#This Row],[SensDe5]],3-Gares[[#This Row],[SensDe5]])) -> 0 | AA17: =IF(Gares[[#This Row],[SensDe6]]=0,0,IF(ISERROR(FIND("$",Gares[[#This Row],[Vers6]]))*ISERROR(FIND("@",Gares[[#This Row],[Vers6]])),Gares[[#This Row],[SensDe6]],3-Gares[[#This Row],[SensDe6]])) -> 0
A18: CHK | B18: Chamarande | F18: =COUNTA($J18:$N18) -> 2 | G18: {=SUM(IF(SUBSTITUTE(SUBSTITUTE(SUBSTITUTE(OFFSET($J$3,0,0,ROWS(Gares[Vers1]),Param!$B$2),"&",""),"$",""),"@","")=$I18,1,0))} -> 2 | H18: =IF(F18=G18,1,0) -> 1 | I18: =Gares[[#This Row],[Abv]] -> CHK | J18: =I19 -> LYO | K18: =I17 -> ETY | P18: =IF(Gares[[#This Row],[Vers1]]="",0,IF(_xlfn.XOR(ISERROR(MATCH(SUBSTITUTE(SUBSTITUTE(SUBSTITUTE(Gares[[#This Row],[Vers1]],"&",""),"$",""),"@",""),$I$2:$I17,0)),NOT(ISERROR(FIND("&",Gares[[#This Row],[Vers1]])))),2,1)) -> 2 | Q18: =IF(Gares[[#This Row],[Vers2]]="",0,IF(_xlfn.XOR(ISERROR(MATCH(SUBSTITUTE(SUBSTITUTE(SUBSTITUTE(Gares[[#This Row],[Vers2]],"&",""),"$",""),"@",""),$I$2:$I17,0)),NOT(ISERROR(FIND("&",Gares[[#This Row],[Vers2]])))),2,1)) -> 1 | R18: =IF(Gares[[#This Row],[Vers3]]="",0,IF(_xlfn.XOR(ISERROR(MATCH(SUBSTITUTE(SUBSTITUTE(SUBSTITUTE(Gares[[#This Row],[Vers3]],"&",""),"$",""),"@",""),$I$2:$I17,0)),NOT(ISERROR(FIND("&",Gares[[#This Row],[Vers3]])))),2,1)) -> 0 | S18: =IF(Gares[[#This Row],[Vers4]]="",0,IF(_xlfn.XOR(ISERROR(MATCH(SUBSTITUTE(SUBSTITUTE(SUBSTITUTE(Gares[[#This Row],[Vers4]],"&",""),"$",""),"@",""),$I$2:$I17,0)),NOT(ISERROR(FIND("&",Gares[[#This Row],[Vers4]])))),2,1)) -> 0 | T18: =IF(Gares[[#This Row],[Vers5]]="",0,IF(_xlfn.XOR(ISERROR(MATCH(SUBSTITUTE(SUBSTITUTE(SUBSTITUTE(Gares[[#This Row],[Vers5]],"&",""),"$",""),"@",""),$I$2:$I17,0)),NOT(ISERROR(FIND("&",Gares[[#This Row],[Vers5]])))),2,1)) -> 0 | U18: =IF(Gares[[#This Row],[Vers6]]="",0,IF(_xlfn.XOR(ISERROR(MATCH(SUBSTITUTE(SUBSTITUTE(SUBSTITUTE(Gares[[#This Row],[Vers6]],"&",""),"$",""),"@",""),$I$2:$I17,0)),NOT(ISERROR(FIND("&",Gares[[#This Row],[Vers6]])))),2,1)) -> 0 | V18: =IF(Gares[[#This Row],[SensDe1]]=0,0,IF(ISERROR(FIND("$",Gares[[#This Row],[Vers1]]))*ISERROR(FIND("@",Gares[[#This Row],[Vers1]])),Gares[[#This Row],[SensDe1]],3-Gares[[#This Row],[SensDe1]])) -> 2 | W18: =IF(Gares[[#This Row],[SensDe2]]=0,0,IF(ISERROR(FIND("$",Gares[[#This Row],[Vers2]]))*ISERROR(FIND("@",Gares[[#This Row],[Vers2]])),Gares[[#This Row],[SensDe2]],3-Gares[[#This Row],[SensDe2]])) -> 1 | X18: =IF(Gares[[#This Row],[SensDe3]]=0,0,IF(ISERROR(FIND("$",Gares[[#This Row],[Vers3]]))*ISERROR(FIND("@",Gares[[#This Row],[Vers3]])),Gares[[#This Row],[SensDe3]],3-Gares[[#This Row],[SensDe3]])) -> 0 | Y18: =IF(Gares[[#This Row],[SensDe4]]=0,0,IF(ISERROR(FIND("$",Gares[[#This Row],[Vers4]]))*ISERROR(FIND("@",Gares[[#This Row],[Vers4]])),Gares[[#This Row],[SensDe4]],3-Gares[[#This Row],[SensDe4]])) -> 0 | Z18: =IF(Gares[[#This Row],[SensDe5]]=0,0,IF(ISERROR(FIND("$",Gares[[#This Row],[Vers5]]))*ISERROR(FIND("@",Gares[[#This Row],[Vers5]])),Gares[[#This Row],[SensDe5]],3-Gares[[#This Row],[SensDe5]])) -> 0 | AA18: =IF(Gares[[#This Row],[SensDe6]]=0,0,IF(ISERROR(FIND("$",Gares[[#This Row],[Vers6]]))*ISERROR(FIND("@",Gares[[#This Row],[Vers6]])),Gares[[#This Row],[SensDe6]],3-Gares[[#This Row],[SensDe6]])) -> 0
A19: LYO | B19: Lardy | F19: =COUNTA($J19:$N19) -> 2 | G19: {=SUM(IF(SUBSTITUTE(SUBSTITUTE(SUBSTITUTE(OFFSET($J$3,0,0,ROWS(Gares[Vers1]),Param!$B$2),"&",""),"$",""),"@","")=$I19,1,0))} -> 2 | H19: =IF(F19=G19,1,0) -> 1 | I19: =Gares[[#This Row],[Abv]] -> LYO | J19: =I20 -> BSO | K19: =I18 -> CHK | P19: =IF(Gares[[#This Row],[Vers1]]="",0,IF(_xlfn.XOR(ISERROR(MATCH(SUBSTITUTE(SUBSTITUTE(SUBSTITUTE(Gares[[#This Row],[Vers1]],"&",""),"$",""),"@",""),$I$2:$I18,0)),NOT(ISERROR(FIND("&",Gares[[#This Row],[Vers1]])))),2,1)) -> 2 | Q19: =IF(Gares[[#This Row],[Vers2]]="",0,IF(_xlfn.XOR(ISERROR(MATCH(SUBSTITUTE(SUBSTITUTE(SUBSTITUTE(Gares[[#This Row],[Vers2]],"&",""),"$",""),"@",""),$I$2:$I18,0)),NOT(ISERROR(FIND("&",Gares[[#This Row],[Vers2]])))),2,1)) -> 1 | R19: =IF(Gares[[#This Row],[Vers3]]="",0,IF(_xlfn.XOR(ISERROR(MATCH(SUBSTITUTE(SUBSTITUTE(SUBSTITUTE(Gares[[#This Row],[Vers3]],"&",""),"$",""),"@",""),$I$2:$I18,0)),NOT(ISERROR(FIND("&",Gares[[#This Row],[Vers3]])))),2,1)) -> 0 | S19: =IF(Gares[[#This Row],[Vers4]]="",0,IF(_xlfn.XOR(ISERROR(MATCH(SUBSTITUTE(SUBSTITUTE(SUBSTITUTE(Gares[[#This Row],[Vers4]],"&",""),"$",""),"@",""),$I$2:$I18,0)),NOT(ISERROR(FIND("&",Gares[[#This Row],[Vers4]])))),2,1)) -> 0 | T19: =IF(Gares[[#This Row],[Vers5]]="",0,IF(_xlfn.XOR(ISERROR(MATCH(SUBSTITUTE(SUBSTITUTE(SUBSTITUTE(Gares[[#This Row],[Vers5]],"&",""),"$",""),"@",""),$I$2:$I18,0)),NOT(ISERROR(FIND("&",Gares[[#This Row],[Vers5]])))),2,1)) -> 0 | U19: =IF(Gares[[#This Row],[Vers6]]="",0,IF(_xlfn.XOR(ISERROR(MATCH(SUBSTITUTE(SUBSTITUTE(SUBSTITUTE(Gares[[#This Row],[Vers6]],"&",""),"$",""),"@",""),$I$2:$I18,0)),NOT(ISERROR(FIND("&",Gares[[#This Row],[Vers6]])))),2,1)) -> 0 | V19: =IF(Gares[[#This Row],[SensDe1]]=0,0,IF(ISERROR(FIND("$",Gares[[#This Row],[Vers1]]))*ISERROR(FIND("@",Gares[[#This Row],[Vers1]])),Gares[[#This Row],[SensDe1]],3-Gares[[#This Row],[SensDe1]])) -> 2 | W19: =IF(Gares[[#This Row],[SensDe2]]=0,0,IF(ISERROR(FIND("$",Gares[[#This Row],[Vers2]]))*ISERROR(FIND("@",Gares[[#This Row],[Vers2]])),Gares[[#This Row],[SensDe2]],3-Gares[[#This Row],[SensDe2]])) -> 1 | X19: =IF(Gares[[#This Row],[SensDe3]]=0,0,IF(ISERROR(FIND("$",Gares[[#This Row],[Vers3]]))*ISERROR(FIND("@",Gares[[#This Row],[Vers3]])),Gares[[#This Row],[SensDe3]],3-Gares[[#This Row],[SensDe3]])) -> 0 | Y19: =IF(Gares[[#This Row],[SensDe4]]=0,0,IF(ISERROR(FIND("$",Gares[[#This Row],[Vers4]]))*ISERROR(FIND("@",Gares[[#This Row],[Vers4]])),Gares[[#This Row],[SensDe4]],3-Gares[[#This Row],[SensDe4]])) -> 0 | Z19: =IF(Gares[[#This Row],[SensDe5]]=0,0,IF(ISERROR(FIND("$",Gares[[#This Row],[Vers5]]))*ISERROR(FIND("@",Gares[[#This Row],[Vers5]])),Gares[[#This Row],[SensDe5]],3-Gares[[#This Row],[SensDe5]])) -> 0 | AA19: =IF(Gares[[#This Row],[SensDe6]]=0,0,IF(ISERROR(FIND("$",Gares[[#This Row],[Vers6]]))*ISERROR(FIND("@",Gares[[#This Row],[Vers6]])),Gares[[#This Row],[SensDe6]],3-Gares[[#This Row],[SensDe6]])) -> 0
A20: BSO | B20: Bouray | F20: =COUNTA($J20:$N20) -> 2 | G20: {=SUM(IF(SUBSTITUTE(SUBSTITUTE(SUBSTITUTE(OFFSET($J$3,0,0,ROWS(Gares[Vers1]),Param!$B$2),"&",""),"$",""),"@","")=$I20,1,0))} -> 2 | H20: =IF(F20=G20,1,0) -> 1 | I20: =Gares[[#This Row],[Abv]] -> BSO | J20: =I21 -> MSX | K20: =I19 -> LYO | P20: =IF(Gares[[#This Row],[Vers1]]="",0,IF(_xlfn.XOR(ISERROR(MATCH(SUBSTITUTE(SUBSTITUTE(SUBSTITUTE(Gares[[#This Row],[Vers1]],"&",""),"$",""),"@",""),$I$2:$I19,0)),NOT(ISERROR(FIND("&",Gares[[#This Row],[Vers1]])))),2,1)) -> 2 | Q20: =IF(Gares[[#This Row],[Vers2]]="",0,IF(_xlfn.XOR(ISERROR(MATCH(SUBSTITUTE(SUBSTITUTE(SUBSTITUTE(Gares[[#This Row],[Vers2]],"&",""),"$",""),"@",""),$I$2:$I19,0)),NOT(ISERROR(FIND("&",Gares[[#This Row],[Vers2]])))),2,1)) -> 1 | R20: =IF(Gares[[#This Row],[Vers3]]="",0,IF(_xlfn.XOR(ISERROR(MATCH(SUBSTITUTE(SUBSTITUTE(SUBSTITUTE(Gares[[#This Row],[Vers3]],"&",""),"$",""),"@",""),$I$2:$I19,0)),NOT(ISERROR(FIND("&",Gares[[#This Row],[Vers3]])))),2,1)) -> 0 | S20: =IF(Gares[[#This Row],[Vers4]]="",0,IF(_xlfn.XOR(ISERROR(MATCH(SUBSTITUTE(SUBSTITUTE(SUBSTITUTE(Gares[[#This Row],[Vers4]],"&",""),"$",""),"@",""),$I$2:$I19,0)),NOT(ISERROR(FIND("&",Gares[[#This Row],[Vers4]])))),2,1)) -> 0 | T20: =IF(Gares[[#This Row],[Vers5]]="",0,IF(_xlfn.XOR(ISERROR(MATCH(SUBSTITUTE(SUBSTITUTE(SUBSTITUTE(Gares[[#This Row],[Vers5]],"&",""),"$",""),"@",""),$I$2:$I19,0)),NOT(ISERROR(FIND("&",Gares[[#This Row],[Vers5]])))),2,1)) -> 0 | U20: =IF(Gares[[#This Row],[Vers6]]="",0,IF(_xlfn.XOR(ISERROR(MATCH(SUBSTITUTE(SUBSTITUTE(SUBSTITUTE(Gares[[#This Row],[Vers6]],"&",""),"$",""),"@",""),$I$2:$I19,0)),NOT(ISERROR(FIND("&",Gares[[#This Row],[Vers6]])))),2,1)) -> 0 | V20: =IF(Gares[[#This Row],[SensDe1]]=0,0,IF(ISERROR(FIND("$",Gares[[#This Row],[Vers1]]))*ISERROR(FIND("@",Gares[[#This Row],[Vers1]])),Gares[[#This Row],[SensDe1]],3-Gares[[#This Row],[SensDe1]])) -> 2 | W20: =IF(Gares[[#This Row],[SensDe2]]=0,0,IF(ISERROR(FIND("$",Gares[[#This Row],[Vers2]]))*ISERROR(FIND("@",Gares[[#This Row],[Vers2]])),Gares[[#This Row],[SensDe2]],3-Gares[[#This Row],[SensDe2]])) -> 1 | X20: =IF(Gares[[#This Row],[SensDe3]]=0,0,IF(ISERROR(FIND("$",Gares[[#This Row],[Vers3]]))*ISERROR(FIND("@",Gares[[#This Row],[Vers3]])),Gares[[#This Row],[SensDe3]],3-Gares[[#This Row],[SensDe3]])) -> 0 | Y20: =IF(Gares[[#This Row],[SensDe4]]=0,0,IF(ISERROR(FIND("$",Gares[[#This Row],[Vers4]]))*ISERROR(FIND("@",Gares[[#This Row],[Vers4]])),Gares[[#This Row],[SensDe4]],3-Gares[[#This Row],[SensDe4]])) -> 0 | Z20: =IF(Gares[[#This Row],[SensDe5]]=0,0,IF(ISERROR(FIND("$",Gares[[#This Row],[Vers5]]))*ISERROR(FIND("@",Gares[[#This Row],[Vers5]])),Gares[[#This Row],[SensDe5]],3-Gares[[#This Row],[SensDe5]])) -> 0 | AA20: =IF(Gares[[#This Row],[SensDe6]]=0,0,IF(ISERROR(FIND("$",Gares[[#This Row],[Vers6]]))*ISERROR(FIND("@",Gares[[#This Row],[Vers6]])),Gares[[#This Row],[SensDe6]],3-Gares[[#This Row],[SensDe6]])) -> 0
